2018-06-26 09:04:01,025 ERROR: Exception on /user [GET] [in /Users/sarahcheng/Documents/Master/GRA/microblog/venv/lib/python3.6/site-packages/flask/app.py:1761]
Traceback (most recent call last):
  File "/Users/sarahcheng/Documents/Master/GRA/microblog/venv/lib/python3.6/site-packages/flask/app.py", line 1813, in full_dispatch_request
    rv = self.dispatch_request()
  File "/Users/sarahcheng/Documents/Master/GRA/microblog/venv/lib/python3.6/site-packages/flask/app.py", line 1791, in dispatch_request
    self.raise_routing_exception(req)
  File "/Users/sarahcheng/Documents/Master/GRA/microblog/venv/lib/python3.6/site-packages/flask/app.py", line 1774, in raise_routing_exception
    raise request.routing_exception
  File "/Users/sarahcheng/Documents/Master/GRA/microblog/venv/lib/python3.6/site-packages/flask/ctx.py", line 336, in match_request
    self.url_adapter.match(return_rule=True)
  File "/Users/sarahcheng/Documents/Master/GRA/microblog/venv/lib/python3.6/site-packages/werkzeug/routing.py", line 1581, in match
    raise NotFound()
werkzeug.exceptions.NotFound: 404 Not Found: The requested URL was not found on the server.  If you entered the URL manually please check your spelling and try again.

During handling of the above exception, another exception occurred:

Traceback (most recent call last):
  File "/Users/sarahcheng/Documents/Master/GRA/microblog/venv/lib/python3.6/site-packages/flask/app.py", line 2292, in wsgi_app
    response = self.full_dispatch_request()
  File "/Users/sarahcheng/Documents/Master/GRA/microblog/venv/lib/python3.6/site-packages/flask/app.py", line 1815, in full_dispatch_request
    rv = self.handle_user_exception(e)
  File "/Users/sarahcheng/Documents/Master/GRA/microblog/venv/lib/python3.6/site-packages/flask/app.py", line 1713, in handle_user_exception
    return self.handle_http_exception(e)
  File "/Users/sarahcheng/Documents/Master/GRA/microblog/venv/lib/python3.6/site-packages/flask/app.py", line 1644, in handle_http_exception
    return handler(e)
  File "/Users/sarahcheng/Documents/Master/GRA/microblog/app/errors.py", line 6, in not_found_error
    return render_template('404.html'), 404
  File "/Users/sarahcheng/Documents/Master/GRA/microblog/venv/lib/python3.6/site-packages/flask/templating.py", line 134, in render_template
    return _render(ctx.app.jinja_env.get_or_select_template(template_name_or_list),
  File "/Users/sarahcheng/Documents/Master/GRA/microblog/venv/lib/python3.6/site-packages/jinja2/environment.py", line 869, in get_or_select_template
    return self.get_template(template_name_or_list, parent, globals)
  File "/Users/sarahcheng/Documents/Master/GRA/microblog/venv/lib/python3.6/site-packages/jinja2/environment.py", line 830, in get_template
    return self._load_template(name, self.make_globals(globals))
  File "/Users/sarahcheng/Documents/Master/GRA/microblog/venv/lib/python3.6/site-packages/jinja2/environment.py", line 804, in _load_template
    template = self.loader.load(self, name, globals)
  File "/Users/sarahcheng/Documents/Master/GRA/microblog/venv/lib/python3.6/site-packages/jinja2/loaders.py", line 125, in load
    code = environment.compile(source, name, filename)
  File "/Users/sarahcheng/Documents/Master/GRA/microblog/venv/lib/python3.6/site-packages/jinja2/environment.py", line 591, in compile
    self.handle_exception(exc_info, source_hint=source_hint)
  File "/Users/sarahcheng/Documents/Master/GRA/microblog/venv/lib/python3.6/site-packages/jinja2/environment.py", line 780, in handle_exception
    reraise(exc_type, exc_value, tb)
  File "/Users/sarahcheng/Documents/Master/GRA/microblog/venv/lib/python3.6/site-packages/jinja2/_compat.py", line 37, in reraise
    raise value.with_traceback(tb)
  File "/Users/sarahcheng/Documents/Master/GRA/microblog/app/templates/404.html", line 3, in template
    {% block_content %}
  File "/Users/sarahcheng/Documents/Master/GRA/microblog/venv/lib/python3.6/site-packages/jinja2/environment.py", line 497, in _parse
    return Parser(self, source, name, encode_filename(filename)).parse()
  File "/Users/sarahcheng/Documents/Master/GRA/microblog/venv/lib/python3.6/site-packages/jinja2/parser.py", line 901, in parse
    result = nodes.Template(self.subparse(), lineno=1)
  File "/Users/sarahcheng/Documents/Master/GRA/microblog/venv/lib/python3.6/site-packages/jinja2/parser.py", line 883, in subparse
    rv = self.parse_statement()
  File "/Users/sarahcheng/Documents/Master/GRA/microblog/venv/lib/python3.6/site-packages/jinja2/parser.py", line 144, in parse_statement
    self.fail_unknown_tag(token.value, token.lineno)
  File "/Users/sarahcheng/Documents/Master/GRA/microblog/venv/lib/python3.6/site-packages/jinja2/parser.py", line 97, in fail_unknown_tag
    return self._fail_ut_eof(name, self._end_token_stack, lineno)
  File "/Users/sarahcheng/Documents/Master/GRA/microblog/venv/lib/python3.6/site-packages/jinja2/parser.py", line 90, in _fail_ut_eof
    self.fail(' '.join(message), lineno)
  File "/Users/sarahcheng/Documents/Master/GRA/microblog/venv/lib/python3.6/site-packages/jinja2/parser.py", line 59, in fail
    raise exc(msg, lineno, self.name, self.filename)
jinja2.exceptions.TemplateSyntaxError: Encountered unknown tag 'block_content'.
