2018-07-09 21:18:23,263 ERROR: Exception on /follow/sarah12110211 [GET] [in /Users/sarahcheng/Documents/Master/GRA/microblog/venv/lib/python3.6/site-packages/flask/app.py:1761]
Traceback (most recent call last):
  File "/Users/sarahcheng/Documents/Master/GRA/microblog/venv/lib/python3.6/site-packages/flask/app.py", line 2292, in wsgi_app
    response = self.full_dispatch_request()
  File "/Users/sarahcheng/Documents/Master/GRA/microblog/venv/lib/python3.6/site-packages/flask/app.py", line 1815, in full_dispatch_request
    rv = self.handle_user_exception(e)
  File "/Users/sarahcheng/Documents/Master/GRA/microblog/venv/lib/python3.6/site-packages/flask/app.py", line 1718, in handle_user_exception
    reraise(exc_type, exc_value, tb)
  File "/Users/sarahcheng/Documents/Master/GRA/microblog/venv/lib/python3.6/site-packages/flask/_compat.py", line 35, in reraise
    raise value
  File "/Users/sarahcheng/Documents/Master/GRA/microblog/venv/lib/python3.6/site-packages/flask/app.py", line 1813, in full_dispatch_request
    rv = self.dispatch_request()
  File "/Users/sarahcheng/Documents/Master/GRA/microblog/venv/lib/python3.6/site-packages/flask/app.py", line 1799, in dispatch_request
    return self.view_functions[rule.endpoint](**req.view_args)
  File "/Users/sarahcheng/Documents/Master/GRA/microblog/venv/lib/python3.6/site-packages/flask_login/utils.py", line 261, in decorated_view
    return func(*args, **kwargs)
  File "/Users/sarahcheng/Documents/Master/GRA/microblog/app/main/routes.py", line 92, in follow
    return redirect(url_for('user',username=username))
  File "/Users/sarahcheng/Documents/Master/GRA/microblog/venv/lib/python3.6/site-packages/flask/helpers.py", line 356, in url_for
    return appctx.app.handle_url_build_error(error, endpoint, values)
  File "/Users/sarahcheng/Documents/Master/GRA/microblog/venv/lib/python3.6/site-packages/flask/app.py", line 2061, in handle_url_build_error
    reraise(exc_type, exc_value, tb)
  File "/Users/sarahcheng/Documents/Master/GRA/microblog/venv/lib/python3.6/site-packages/flask/_compat.py", line 35, in reraise
    raise value
  File "/Users/sarahcheng/Documents/Master/GRA/microblog/venv/lib/python3.6/site-packages/flask/helpers.py", line 345, in url_for
    force_external=external)
  File "/Users/sarahcheng/Documents/Master/GRA/microblog/venv/lib/python3.6/site-packages/werkzeug/routing.py", line 1776, in build
    raise BuildError(endpoint, values, method, self)
werkzeug.routing.BuildError: Could not build url for endpoint 'user' with values ['username']. Did you mean 'main.user' instead?
2018-07-09 22:05:32,727 ERROR: Exception on /auth/callback/facebook [GET] [in /Users/sarahcheng/Documents/Master/GRA/microblog/venv/lib/python3.6/site-packages/flask/app.py:1761]
Traceback (most recent call last):
  File "/Users/sarahcheng/Documents/Master/GRA/microblog/venv/lib/python3.6/site-packages/flask/app.py", line 2292, in wsgi_app
    response = self.full_dispatch_request()
  File "/Users/sarahcheng/Documents/Master/GRA/microblog/venv/lib/python3.6/site-packages/flask/app.py", line 1815, in full_dispatch_request
    rv = self.handle_user_exception(e)
  File "/Users/sarahcheng/Documents/Master/GRA/microblog/venv/lib/python3.6/site-packages/flask/app.py", line 1718, in handle_user_exception
    reraise(exc_type, exc_value, tb)
  File "/Users/sarahcheng/Documents/Master/GRA/microblog/venv/lib/python3.6/site-packages/flask/_compat.py", line 35, in reraise
    raise value
  File "/Users/sarahcheng/Documents/Master/GRA/microblog/venv/lib/python3.6/site-packages/flask/app.py", line 1813, in full_dispatch_request
    rv = self.dispatch_request()
  File "/Users/sarahcheng/Documents/Master/GRA/microblog/venv/lib/python3.6/site-packages/flask/app.py", line 1799, in dispatch_request
    return self.view_functions[rule.endpoint](**req.view_args)
  File "/Users/sarahcheng/Documents/Master/GRA/microblog/app/auth/routes.py", line 94, in oauth_callback
    social_id, username, email,picture,friends= oauth.callback()
  File "/Users/sarahcheng/Documents/Master/GRA/microblog/oauth.py", line 58, in callback
    print('payload: ',payload)
NameError: name 'payload' is not defined
