2018-07-10 20:21:49,510 ERROR: Exception on /api/users/11 [PUT] [in /Users/sarahcheng/Documents/Master/GRA/microblog/venv/lib/python3.6/site-packages/flask/app.py:1761]
Traceback (most recent call last):
  File "/Users/sarahcheng/Documents/Master/GRA/microblog/venv/lib/python3.6/site-packages/flask/app.py", line 2292, in wsgi_app
    response = self.full_dispatch_request()
  File "/Users/sarahcheng/Documents/Master/GRA/microblog/venv/lib/python3.6/site-packages/flask/app.py", line 1815, in full_dispatch_request
    rv = self.handle_user_exception(e)
  File "/Users/sarahcheng/Documents/Master/GRA/microblog/venv/lib/python3.6/site-packages/flask/app.py", line 1718, in handle_user_exception
    reraise(exc_type, exc_value, tb)
  File "/Users/sarahcheng/Documents/Master/GRA/microblog/venv/lib/python3.6/site-packages/flask/_compat.py", line 35, in reraise
    raise value
  File "/Users/sarahcheng/Documents/Master/GRA/microblog/venv/lib/python3.6/site-packages/flask/app.py", line 1813, in full_dispatch_request
    rv = self.dispatch_request()
  File "/Users/sarahcheng/Documents/Master/GRA/microblog/venv/lib/python3.6/site-packages/flask/app.py", line 1799, in dispatch_request
    return self.view_functions[rule.endpoint](**req.view_args)
  File "/Users/sarahcheng/Documents/Master/GRA/microblog/app/api/users.py", line 70, in update_user
    return jsonify(user.to_dict())
  File "/Users/sarahcheng/Documents/Master/GRA/microblog/app/models.py", line 126, in to_dict
    'self': url_for('api.get_user', id=self.id),
  File "/Users/sarahcheng/Documents/Master/GRA/microblog/venv/lib/python3.6/site-packages/flask/helpers.py", line 356, in url_for
    return appctx.app.handle_url_build_error(error, endpoint, values)
  File "/Users/sarahcheng/Documents/Master/GRA/microblog/venv/lib/python3.6/site-packages/flask/app.py", line 2061, in handle_url_build_error
    reraise(exc_type, exc_value, tb)
  File "/Users/sarahcheng/Documents/Master/GRA/microblog/venv/lib/python3.6/site-packages/flask/_compat.py", line 35, in reraise
    raise value
  File "/Users/sarahcheng/Documents/Master/GRA/microblog/venv/lib/python3.6/site-packages/flask/helpers.py", line 345, in url_for
    force_external=external)
  File "/Users/sarahcheng/Documents/Master/GRA/microblog/venv/lib/python3.6/site-packages/werkzeug/routing.py", line 1776, in build
    raise BuildError(endpoint, values, method, self)
werkzeug.routing.BuildError: Could not build url for endpoint 'api.get_user'. Did you forget to specify values ['id']?
2018-07-10 20:24:11,950 ERROR: Exception on /api/users/11 [PUT] [in /Users/sarahcheng/Documents/Master/GRA/microblog/venv/lib/python3.6/site-packages/flask/app.py:1761]
Traceback (most recent call last):
  File "/Users/sarahcheng/Documents/Master/GRA/microblog/venv/lib/python3.6/site-packages/flask/app.py", line 2292, in wsgi_app
    response = self.full_dispatch_request()
  File "/Users/sarahcheng/Documents/Master/GRA/microblog/venv/lib/python3.6/site-packages/flask/app.py", line 1815, in full_dispatch_request
    rv = self.handle_user_exception(e)
  File "/Users/sarahcheng/Documents/Master/GRA/microblog/venv/lib/python3.6/site-packages/flask/app.py", line 1718, in handle_user_exception
    reraise(exc_type, exc_value, tb)
  File "/Users/sarahcheng/Documents/Master/GRA/microblog/venv/lib/python3.6/site-packages/flask/_compat.py", line 35, in reraise
    raise value
  File "/Users/sarahcheng/Documents/Master/GRA/microblog/venv/lib/python3.6/site-packages/flask/app.py", line 1813, in full_dispatch_request
    rv = self.dispatch_request()
  File "/Users/sarahcheng/Documents/Master/GRA/microblog/venv/lib/python3.6/site-packages/flask/app.py", line 1799, in dispatch_request
    return self.view_functions[rule.endpoint](**req.view_args)
  File "/Users/sarahcheng/Documents/Master/GRA/microblog/app/api/users.py", line 71, in update_user
    return jsonify(user.to_dict())
  File "/Users/sarahcheng/Documents/Master/GRA/microblog/app/models.py", line 126, in to_dict
    'self': url_for('api.get_user', id=self.id),
  File "/Users/sarahcheng/Documents/Master/GRA/microblog/venv/lib/python3.6/site-packages/flask/helpers.py", line 356, in url_for
    return appctx.app.handle_url_build_error(error, endpoint, values)
  File "/Users/sarahcheng/Documents/Master/GRA/microblog/venv/lib/python3.6/site-packages/flask/app.py", line 2061, in handle_url_build_error
    reraise(exc_type, exc_value, tb)
  File "/Users/sarahcheng/Documents/Master/GRA/microblog/venv/lib/python3.6/site-packages/flask/_compat.py", line 35, in reraise
    raise value
  File "/Users/sarahcheng/Documents/Master/GRA/microblog/venv/lib/python3.6/site-packages/flask/helpers.py", line 345, in url_for
    force_external=external)
  File "/Users/sarahcheng/Documents/Master/GRA/microblog/venv/lib/python3.6/site-packages/werkzeug/routing.py", line 1776, in build
    raise BuildError(endpoint, values, method, self)
werkzeug.routing.BuildError: Could not build url for endpoint 'api.get_user'. Did you forget to specify values ['id']?
